Workbook

Sheet README
A1: Private AI — 3-year financial model (regenerated 2026-10-20)
A3: What this is
A4: A monthly, formula-driven model for 36 months from Oct 19, 2026, with four scenarios side by side.
A5: It replaces the original 3-year spreadsheet, which wasn't available; the 'Original plan' scenario is calibrated to that model's published results.
A7: Sheets
A8: Summary — key results for all four scenarios.
A9: Checks — Original plan scenario vs the figures in the founder brief.
A10: Inputs — every assumption, per scenario, with its source in column G.
A11: Schedules — month-by-month signings and industrial project revenue per scenario.
A12: M_Original / M_Conservative / M_Base / M_Stretch — the monthly models (formulas only).
A14: Colour code
A15: Blue text = input. Black = formula. Green = link to another sheet. Yellow fill = key assumption or value to confirm.
... A29: Built by private-ai/model/build_model.py.

Sheet Summary
A1: Private AI — 3-year model summary (as of 2026-10-20)
A2: Revised scenarios follow 14-revised-plan-2026-10-20.md; 'Original plan' reproduces the founder brief's figures (see Checks). All values are formulas; change inputs on the Inputs and Schedules sheets.
A4: Metric | B4: Original plan | C4: Conservative | D4: Base | E4: Stretch
A5: Revenue, Year 1 | B5: =SUMIF(M_Original!$C$3:$AL$3,1,M_Original!$C$25:$AL$25) -> 157702 | C5: =SUMIF(M_Conservative!$C$3:$AL$3,1,M_Conservative!$C$25:$AL$25) -> 112820 | D5: =SUMIF(M_Base!$C$3:$AL$3,1,M_Base!$C$25:$AL$25) -> 190160 | E5: =SUMIF(M_Stretch!$C$3:$AL$3,1,M_Stretch!$C$25:$AL$25) -> 298100
A6: Revenue, Year 2 | B6: =SUMIF(M_Original!$C$3:$AL$3,2,M_Original!$C$25:$AL$25) -> 465012.53 | C6: =SUMIF(M_Conservative!$C$3:$AL$3,2,M_Conservative!$C$25:$AL$25) -> 292010 | D6: =SUMIF(M_Base!$C$3:$AL$3,2,M_Base!$C$25:$AL$25) -> 507195 | E6: =SUMIF(M_Stretch!$C$3:$AL$3,2,M_Stretch!$C$25:$AL$25) -> 867137.5
A7: Revenue, Year 3 | B7: =SUMIF(M_Original!$C$3:$AL$3,3,M_Original!$C$25:$AL$25) -> 860034.3 | C7: =SUMIF(M_Conservative!$C$3:$AL$3,3,M_Conservative!$C$25:$AL$25) -> 529025 | D7: =SUMIF(M_Base!$C$3:$AL$3,3,M_Base!$C$25:$AL$25) -> 897969 | E7: =SUMIF(M_Stretch!$C$3:$AL$3,3,M_Stretch!$C$25:$AL$25) -> 1528141.5
A8: Gross margin, Year 1 | B8: =IFERROR(SUMIF(M_Original!$C$3:$AL$3,1,M_Original!$C$29:$AL$29)/SUMIF(M_Original!$C$3:$AL$3,1,M_Original!$C$25:$AL$25),0) -> 0.65045973 | C8: =IFERROR(SUMIF(M_Conservative!$C$3:$AL$3,1,M_Conservative!$C$29:$AL$29)/SUMIF(M_Conservative!$C$3:$AL$3,1,M_Conservative!$C$25:$AL$25),0) -> 0.67142351 | D8: =IFERROR(SUMIF(M_Base!$C$3:$AL$3,1,M_Base!$C$29:$AL$29)/SUMIF(M_Base!$C$3:$AL$3,1,M_Base!$C$25:$AL$25),0) -> 0.67640408 | E8: =IFERROR(SUMIF(M_Stretch!$C$3:$AL$3,1,M_Stretch!$C$29:$AL$29)/SUMIF(M_Stretch!$C$3:$AL$3,1,M_Stretch!$C$25:$AL$25),0) -> 0.67267695
A9: Gross margin, Year 2 | B9: =IFERROR(SUMIF(M_Original!$C$3:$AL$3,2,M_Original!$C$29:$AL$29)/SUMIF(M_Original!$C$3:$AL$3,2,M_Original!$C$25:$AL$25),0) -> 0.67292896 | C9: =IFERROR(SUMIF(M_Conservative!$C$3:$AL$3,2,M_Conservative!$C$29:$AL$29)/SUMIF(M_Conservative!$C$3:$AL$3,2,M_Conservative!$C$25:$AL$25),0) -> 0.69371768 | D9: =IFERROR(SUMIF(M_Base!$C$3:$AL$3,2,M_Base!$C$29:$AL$29)/SUMIF(M_Base!$C$3:$AL$3,2,M_Base!$C$25:$AL$25),0) -> 0.6982763 | E9: =IFERROR(SUMIF(M_Stretch!$C$3:$AL$3,2,M_Stretch!$C$29:$AL$29)/SUMIF(M_Stretch!$C$3:$AL$3,2,M_Stretch!$C$25:$AL$25),0) -> 0.69278416
A10: Gross margin, Year 3 | B10: =IFERROR(SUMIF(M_Original!$C$3:$AL$3,3,M_Original!$C$29:$AL$29)/SUMIF(M_Original!$C$3:$AL$3,3,M_Original!$C$25:$AL$25),0) -> 0.68570481 | C10: =IFERROR(SUMIF(M_Conservative!$C$3:$AL$3,3,M_Conservative!$C$29:$AL$29)/SUMIF(M_Conservative!$C$3:$AL$3,3,M_Conservative!$C$25:$AL$25),0) -> 0.69941224 | D10: =IFERROR(SUMIF(M_Base!$C$3:$AL$3,3,M_Base!$C$29:$AL$29)/SUMIF(M_Base!$C$3:$AL$3,3,M_Base!$C$25:$AL$25),0) -> 0.70248979 | E10: =IFERROR(SUMIF(M_Stretch!$C$3:$AL$3,3,M_Stretch!$C$29:$AL$29)/SUMIF(M_Stretch!$C$3:$AL$3,3,M_Stretch!$C$25:$AL$25),0) -> 0.70247547
A11: Operating result, Year 1 | B11: =SUMIF(M_Original!$C$3:$AL$3,1,M_Original!$C$41:$AL$41) -> -95000.2 | C11: =SUMIF(M_Conservative!$C$3:$AL$3,1,M_Conservative!$C$41:$AL$41) -> -118504 | D11: =SUMIF(M_Base!$C$3:$AL$3,1,M_Base!$C$41:$AL$41) -> -65629 | E11: =SUMIF(M_Stretch!$C$3:$AL$3,1,M_Stretch!$C$41:$AL$41) -> 6271
A12: Operating result, Year 2 | B12: =SUMIF(M_Original!$C$3:$AL$3,2,M_Original!$C$41:$AL$41) -> 15000.396 | C12: =SUMIF(M_Conservative!$C$3:$AL$3,2,M_Conservative!$C$41:$AL$41) -> -33522.5 | D12: =SUMIF(M_Base!$C$3:$AL$3,2,M_Base!$C$41:$AL$41) -> 78133.917 | E12: =SUMIF(M_Stretch!$C$3:$AL$3,2,M_Stretch!$C$41:$AL$41) -> 283485.79
A13: Operating result, Year 3 | B13: =SUMIF(M_Original!$C$3:$AL$3,3,M_Original!$C$41:$AL$41) -> 154999.66 | C13: =SUMIF(M_Conservative!$C$3:$AL$3,3,M_Conservative!$C$41:$AL$41) -> 31568.229 | D13: =SUMIF(M_Base!$C$3:$AL$3,3,M_Base!$C$41:$AL$41) -> 217384.05 | E13: =SUMIF(M_Stretch!$C$3:$AL$3,3,M_Stretch!$C$41:$AL$41) -> 625051.93
A14: Industrial revenue, Year 1 | B14: =SUMIF(M_Original!$C$3:$AL$3,1,M_Original!$C$23:$AL$23)+SUMIF(M_Original!$C$3:$AL$3,1,M_Original!$C$24:$AL$24) -> 0 | C14: =SUMIF(M_Conservative!$C$3:$AL$3,1,M_Conservative!$C$23:$AL$23)+SUMIF(M_Conservative!$C$3:$AL$3,1,M_Conservative!$C$24:$AL$24) -> 19600 | D14: =SUMIF(M_Base!$C$3:$AL$3,1,M_Base!$C$23:$AL$23)+SUMIF(M_Base!$C$3:$AL$3,1,M_Base!$C$24:$AL$24) -> 50500 | E14: =SUMIF(M_Stretch!$C$3:$AL$3,1,M_Stretch!$C$23:$AL$23)+SUMIF(M_Stretch!$C$3:$AL$3,1,M_Stretch!$C$24:$AL$24) -> 97200
A15: Industrial revenue, Year 2 | B15: =SUMIF(M_Original!$C$3:$AL$3,2,M_Original!$C$23:$AL$23)+SUMIF(M_Original!$C$3:$AL$3,2,M_Original!$C$24:$AL$24) -> 92298 | C15: =SUMIF(M_Conservative!$C$3:$AL$3,2,M_Conservative!$C$23:$AL$23)+SUMIF(M_Conservative!$C$3:$AL$3,2,M_Conservative!$C$24:$AL$24) -> 61200 | D15: =SUMIF(M_Base!$C$3:$AL$3,2,M_Base!$C$23:$AL$23)+SUMIF(M_Base!$C$3:$AL$3,2,M_Base!$C$24:$AL$24) -> 115000 | E15: =SUMIF(M_Stretch!$C$3:$AL$3,2,M_Stretch!$C$23:$AL$23)+SUMIF(M_Stretch!$C$3:$AL$3,2,M_Stretch!$C$24:$AL$24) -> 221600
A16: Industrial revenue, Year 3 | B16: =SUMIF(M_Original!$C$3:$AL$3,3,M_Original!$C$23:$AL$23)+SUMIF(M_Original!$C$3:$AL$3,3,M_Original!$C$24:$AL$24) -> 108840 | C16: =SUMIF(M_Conservative!$C$3:$AL$3,3,M_Conservative!$C$23:$AL$23)+SUMIF(M_Conservative!$C$3:$AL$3,3,M_Conservative!$C$24:$AL$24) -> 79400 | D16: =SUMIF(M_Base!$C$3:$AL$3,3,M_Base!$C$23:$AL$23)+SUMIF(M_Base!$C$3:$AL$3,3,M_Base!$C$24:$AL$24) -> 156000 | E16: =SUMIF(M_Stretch!$C$3:$AL$3,3,M_Stretch!$C$23:$AL$23)+SUMIF(M_Stretch!$C$3:$AL$3,3,M_Stretch!$C$24:$AL$24) -> 281200
A17: Professional clients incl. TWK, month 12 (signed) | B17: =SUM(M_Original!$C$8:N8)+SUM(M_Original!$C$7:N7) -> 4 | C17: =SUM(M_Conservative!$C$8:N8)+SUM(M_Conservative!$C$7:N7) -> 3 | D17: =SUM(M_Base!$C$8:N8)+SUM(M_Base!$C$7:N7) -> 4 | E17: =SUM(M_Stretch!$C$8:N8)+SUM(M_Stretch!$C$7:N7) -> 5
A18: Professional clients incl. TWK, month 24 (signed) | B18: =SUM(M_Original!$C$8:Z8)+SUM(M_Original!$C$7:Z7) -> 11 | C18: =SUM(M_Conservative!$C$8:Z8)+SUM(M_Conservative!$C$7:Z7) -> 8 | D18: =SUM(M_Base!$C$8:Z8)+SUM(M_Base!$C$7:Z7) -> 11 | E18: =SUM(M_Stretch!$C$8:Z8)+SUM(M_Stretch!$C$7:Z7) -> 14
A19: Professional clients incl. TWK, month 36 (signed) | B19: =SUM(M_Original!$C$8:AL8)+SUM(M_Original!$C$7:AL7) -> 20 | C19: =SUM(M_Conservative!$C$8:AL8)+SUM(M_Conservative!$C$7:AL7) -> 14 | D19: =SUM(M_Base!$C$8:AL8)+SUM(M_Base!$C$7:AL7) -> 20 | E19: =SUM(M_Stretch!$C$8:AL8)+SUM(M_Stretch!$C$7:AL7) -> 25
A20: MRR, month 6 | B20: =M_Original!H26 -> 6813.5 | C20: =M_Conservative!H26 -> 3650 | D20: =M_Base!H26 -> 5800 | E20: =M_Stretch!H26 -> 6950
A21: MRR, month 9 | B21: =M_Original!K26 -> 9827 | C21: =M_Conservative!K26 -> 4050 | D21: =M_Base!K26 -> 8800 | E21: =M_Stretch!K26 -> 11650
A22: MRR, month 12 | B22: =M_Original!N26 -> 12840.5 | C22: =M_Conservative!N26 -> 7600 | D22: =M_Base!N26 -> 12800 | E22: =M_Stretch!N26 -> 20600
A23: MRR, month 24 | B23: =M_Original!Z26 -> 29303.4 | C23: =M_Conservative!Z26 -> 21187.5 | D23: =M_Base!Z26 -> 38815 | E23: =M_Stretch!Z26 -> 63090
A24: MRR, month 36 | B24: =M_Original!AL26 -> 60092.865 | C24: =M_Conservative!AL26 -> 41458.125 | D24: =M_Base!AL26 -> 68865.75 | E24: =M_Stretch!AL26 -> 116160.75
A25: First month MRR reaches $20,000 | B25: =IFERROR(INDEX(M_Original!$C$2:$AL$2,MATCH(TRUE(),INDEX(M_Original!$C$26:$AL$26>=20000,0),0)),"after month 36") -> 20 | C25: =IFERROR(INDEX(M_Conservative!$C$2:$AL$2,MATCH(TRUE(),INDEX(M_Conservative!$C$26:$AL$26>=20000,0),0)),"after month 36") -> 23 | D25: =IFERROR(INDEX(M_Base!$C$2:$AL$2,MATCH(TRUE(),INDEX(M_Base!$C$26:$AL$26>=20000,0),0)),"after month 36") -> 16 | E25: =IFERROR(INDEX(M_Stretch!$C$2:$AL$2,MATCH(TRUE(),INDEX(M_Stretch!$C$26:$AL$26>=20000,0),0)),"after month 36") -> 12
A26: Breakeven: first month the trailing-12-month operating result is positive | B26: =IFERROR(INDEX(M_Original!$C$2:$AL$2,MATCH(TRUE(),INDEX(M_Original!$C$42:$AL$42>0,0),0)),"after month 36") -> 24 | C26: =IFERROR(INDEX(M_Conservative!$C$2:$AL$2,MATCH(TRUE(),INDEX(M_Conservative!$C$42:$AL$42>0,0),0)),"after month 36") -> 30 | D26: =IFERROR(INDEX(M_Base!$C$2:$AL$2,MATCH(TRUE(),INDEX(M_Base!$C$42:$AL$42>0,0),0)),"after month 36") -> 18 | E26: =IFERROR(INDEX(M_Stretch!$C$2:$AL$2,MATCH(TRUE(),INDEX(M_Stretch!$C$42:$AL$42>0,0),0)),"after month 36") -> 12
A27: Lowest cumulative cash before funding (trough) | B27: =MIN(M_Original!$C$54:$AL$54) -> -186336.63 | C27: =MIN(M_Conservative!$C$54:$AL$54) -> -264089.53 | D27: =MIN(M_Base!$C$54:$AL$54) -> -122927.97 | E27: =MIN(M_Stretch!$C$54:$AL$54) -> -82805.567
A28: Operating buffer (months x Year-1 average monthly costs) | B28: =Inputs!C61*SUMIF(M_Original!$C$3:$AL$3,1,M_Original!$C$40:$AL$40)/12 -> 98789.5 | C28: =Inputs!D61*SUMIF(M_Conservative!$C$3:$AL$3,1,M_Conservative!$C$40:$AL$40)/12 -> 97127 | D28: =Inputs!E61*SUMIF(M_Base!$C$3:$AL$3,1,M_Base!$C$40:$AL$40)/12 -> 97127 | E28: =Inputs!F61*SUMIF(M_Stretch!$C$3:$AL$3,1,M_Stretch!$C$40:$AL$40)/12 -> 97127
A29: Capital needed (trough + buffer) | B29: =-B27+B28 -> 285126.13 | C29: =-C27+C28 -> 361216.53 | D29: =-D27+D28 -> 220054.97 | E29: =-E27+E28 -> 179932.57
A30: Planned raise (debt + equity + founder capital) | B30: =Inputs!C56+Inputs!C60+Inputs!C54 -> 400000 | C30: =Inputs!D56+Inputs!D60+Inputs!D54 -> 400000 | D30: =Inputs!E56+Inputs!E60+Inputs!E54 -> 400000 | E30: =Inputs!F56+Inputs!F60+Inputs!F54 -> 400000
A31: Lowest cash balance with the planned raise (negative = bridge or founder capital needed before funding closes) | B31: =MIN(M_Original!$C$53:$AL$53) -> -86084.667 | C31: =MIN(M_Conservative!$C$53:$AL$53) -> -84324.667 | D31: =MIN(M_Base!$C$53:$AL$53) -> -78884.667 | E31: =MIN(M_Stretch!$C$53:$AL$53) -> -73044.667
A32: Cash balance, month 36 | B32: =M_Original!AL53 -> 356340.16 | C32: =M_Conservative!AL53 -> 160882.03 | D32: =M_Base!AL53 -> 511229.27 | E32: =M_Stretch!AL53 -> 1196149

Sheet Checks
A1: Checks — Original plan scenario vs the founder brief
A2: The original spreadsheet isn't available. The Original plan scenario is calibrated (industrial project revenue and unitemized costs) so revenue and operating results match the brief. Gross margin is a test of the line margins.
A4: Metric | B4: Source figure | C4: Model (Original plan) | D4: Difference | E4: Source
A5: Revenue, Year 1 | B5: 155000 | C5: =Summary!B5 -> 157702 | D5: =C5-B5 -> 2702 | E5: Founder brief, section K
A6: Revenue, Year 2 | B6: 465000 | C6: =Summary!B6 -> 465012.53 | D6: =C6-B6 -> 12.525 | E6: Founder brief, section K
A7: Revenue, Year 3 | B7: 860000 | C7: =Summary!B7 -> 860034.3 | D7: =C7-B7 -> 34.30375 | E7: Founder brief, section K
A8: Gross margin, Year 1 | B8: 0.66 | C8: =Summary!B8 -> 0.65045973 | D8: =C8-B8 -> -0.0095402722 | E8: Founder brief, section K
A9: Gross margin, Year 2 | B9: 0.68 | C9: =Summary!B9 -> 0.67292896 | D9: =C9-B9 -> -0.007071037 | E9: Founder brief, section K
A10: Gross margin, Year 3 | B10: 0.69 | C10: =Summary!B10 -> 0.68570481 | D10: =C10-B10 -> -0.0042951879 | E10: Founder brief, section K
A11: Operating result, Year 1 | B11: -95000 | C11: =Summary!B11 -> -95000.2 | D11: =C11-B11 -> -0.2 | E11: Founder brief, section K
A12: Operating result, Year 2 | B12: 15000 | C12: =Summary!B12 -> 15000.396 | D12: =C12-B12 -> 0.39625 | E12: Founder brief, section K
A13: Operating result, Year 3 | B13: 155000 | C13: =Summary!B13 -> 154999.66 | D13: =C13-B13 -> -0.3393125 | E13: Founder brief, section K
A14: Industrial revenue, Year 3 | B14: 129000 | C14: =Summary!B16 -> 108840 | D14: =C14-B14 -> -20160 | E14: Brief: Year-3 mix 15% of ~$860K

Sheet Inputs
A1: Inputs — Private AI 3-year model (as of 2026-10-20)
A2: Blue = input you can change. Yellow fill = key assumption or a value still to confirm. Column G gives the source or basis for every number.
A4: Parameter | B4: Unit | C4: Original plan | D4: Conservative | E4: Base | F4: Stretch | G4: Source / basis
A5: Professional-firm clients
A6: TWK signing month | B6: month | C6: 1 | D6: 1 | E6: 1 | F6: 1 | G6: Assumption: TWK pilot starts week 1 (Oct 19, 2026)
A7: TWK setup fee (after discount) | B7: $ | C7: 20000 | D7: 20000 | E7: 20000 | F7: 20000 | G7: Assumption; discount amount not in source (TODO)
A8: TWK subscription | B8: $/month | C8: 3800 | D8: 3000 | E8: 3800 | F8: 3800 | G8: Assumption; TWK tier not in source (TODO)
A9: Setup fee per other client | B9: $ | C9: 19111 | D9: 15000 | E9: 19000 | F9: 25000 | G9: Founder brief, prompts/init.md: unit economics $25,000, range $15,000–40,000. Base uses the original model's implied ~$19,100; conservative the range floor; stretch the unit-economics figure | Original column calibrated to the brief's Year-3 revenue mix (Checks)
A10: Subscription per other client (blended) | B10: $/month | C10: 2490 | D10: 2500 | E10: 2500 | F10: 3500 | G10: Founder brief, prompts/init.md: Starter $2,500, Professional $4,500–6,500. Base uses the original model's implied ~$2,490 average; stretch a half-Starter, half-Professional blend | Original column calibrated to the brief's Year-3 revenue mix (Checks)
A11: Share of setup billed at signing | B11: % | C11: 0 | D11: 0.5 | E11: 0.5 | F11: 0.5 | G11: Decision Oct 20, 2026 (50% at signing); original assumed billed at install
A12: Months from signing to acceptance | B12: months | C12: 2 | D12: 2 | E12: 2 | F12: 2 | G12: Assumption; Phase 1 runs 12 weeks
A13: Annual subscription escalator | B13: % | C13: 0.05 | D13: 0.05 | E13: 0.05 | F13: 0.05 | G13: Founder brief, prompts/init.md: 5% annual escalator (applied per model year)
A14: Add-on revenue per adopting client | B14: $/month | C14: 1000 | D14: 1000 | E14: 1000 | F14: 1000 | G14: Founder brief, prompts/init.md: $12,000/yr per client in Years 2–3
A15: Share of clients buying add-ons | B15: % | C15: 0.5235 | D15: 0.25 | E15: 0.5 | F15: 0.75 | G15: Original: unit economics assume 1–2 add-ons; revised shares are Analysis, 14-revised-plan-2026-10-20.md | Original column calibrated to the brief's Year-3 revenue mix (Checks)
A16: Add-ons start (months after acceptance) | B16: months | C16: 3 | D16: 3 | E16: 3 | F16: 3 | G16: Founder brief, prompts/init.md: add-ons after the first quarter
A17: Hardware cost per install | B17: $ | C17: 28000 | D17: 28000 | E17: 28000 | F17: 28000 | G17: Founder brief, prompts/init.md: unit economics $28,000
A18: Hardware pass-through margin | B18: % | C18: 0.08 | D18: 0.08 | E18: 0.08 | F18: 0.08 | G18: Founder brief, prompts/init.md: cost plus 8%
A19: Industrial
A20: Contractor compliance setup | B20: $ | C20: 0 | D20: 3000 | E20: 4000 | F20: 5000 | G20: Founder brief, prompts/init.md: $2,500–6,000; case values per Analysis, 14-revised-plan-2026-10-20.md
A21: Contractor compliance retainer | B21: $/month | C21: 0 | D21: 400 | E21: 500 | F21: 600 | G21: Founder brief, prompts/init.md: $400–900/month; expect low end until proven (Analysis, 14-revised-plan-2026-10-20.md)
A22: Gross margin by line
A23: Setup | B23: % | C23: 0.55 | D23: 0.55 | E23: 0.55 | F23: 0.55 | G23: Founder brief, prompts/init.md
A24: Subscription | B24: % | C24: 0.7 | D24: 0.7 | E24: 0.7 | F24: 0.7 | G24: Founder brief, prompts/init.md
A25: Workflow add-ons | B25: % | C25: 0.85 | D25: 0.85 | E25: 0.85 | F25: 0.85 | G25: Founder brief, prompts/init.md
A26: Hardware margin | B26: % | C26: 1 | D26: 1 | E26: 1 | F26: 1 | G26: Founder brief, prompts/init.md
A27: Contractor compliance | B27: % | C27: 0.8 | D27: 0.8 | E27: 0.8 | F27: 0.8 | G27: Founder brief, prompts/init.md: 75–85% (midpoint)
A28: Industrial projects | B28: % | C28: 0.65 | D28: 0.65 | E28: 0.65 | F28: 0.65 | G28: Founder brief, prompts/init.md: services range 55–85%; weekly target 60%+ (assumed 65%)
A29: People
A30: Founder salary, Year 1 | B30: $/yr | C30: 70000 | D30: 70000 | E30: 70000 | F30: 70000 | G30: Founder brief, prompts/init.md
A31: Founder salary, Year 2 | B31: $/yr | C31: 100000 | D31: 100000 | E31: 100000 | F31: 100000 | G31: Founder brief, prompts/init.md
A32: Founder salary, Year 3 | B32: $/yr | C32: 130000 | D32: 130000 | E32: 130000 | F32: 130000 | G32: Founder brief, prompts/init.md
A33: Employer payroll taxes on founder salary | B33: % | C33: 0.0765 | D33: 0.0765 | E33: 0.0765 | F33: 0.0765 | G33: Employer FICA rate (Social Security 6.2% + Medicare 1.45%)
A34: First hire: start month | B34: month | C34: 10 | D34: 26 | E34: 17 | F34: 14 | G34: Original: months 9–12 (Founder brief, prompts/init.md). Revised: the month after MRR first reaches ~$20K in that scenario (see Summary), per Analysis, 14-revised-plan-2026-10-20.md
A35: First hire: loaded annual cost | B35: $/yr | C35: 82500 | D35: 87500 | E35: 87500 | F35: 87500 | G35: Original ~$70–95K (Founder brief, prompts/init.md); revised ~$74–101K at 1.35x (BLS ECEC) — midpoints
A36: Second hire: start month | B36: month | C36: 24 | D36: 37 | E36: 29 | F36: 22 | G36: Original months 22–26 (Founder brief, prompts/init.md). Revised: when MRR reaches ~$45K in that scenario (37 = not within the model horizon), per Analysis, 14-revised-plan-2026-10-20.md
A37: Second hire: loaded annual cost | B37: $/yr | C37: 97500 | D37: 105000 | E37: 105000 | F37: 105000 | G37: Original ~$80–115K (Founder brief, prompts/init.md); revised $65–90K base x1.35 — midpoints
A38: Contract engineer + student: start month | B38: month | C38: 37 | D38: 6 | E38: 6 | F38: 6 | G38: Analysis, 14-revised-plan-2026-10-20.md; ends when the first hire starts; original plan had none
A39: Contract engineer | B39: $/month | C39: 0 | D39: 1400 | E39: 1400 | F39: 1400 | G39: Analysis, 14-revised-plan-2026-10-20.md: $600–2,200/month (midpoint)
A40: Student worker | B40: $/month | C40: 0 | D40: 900 | E40: 900 | F40: 900 | G40: Analysis, 14-revised-plan-2026-10-20.md: $15–20/hr, 10–15 hrs/week (approx. midpoint)
A41: Other operating costs
...

Sheet Schedules
A1: Schedules — monthly signings and project revenue by scenario (inputs)
A2: Month 1 starts Oct 19, 2026. CPA firms close May–December (tax season Jan–Apr); law firms year-round. Professional signings exclude TWK. Edit the blue cells.
A4: Row | B4: Total | C4: 1 | D4: 2 | E4: 3 | F4: 4 | G4: 5 | H4: 6 | I4: 7 | J4: 8 | K4: 9 | L4: 10 | M4: 11 | N4: 12 | O4: 13 | P4: 14 | Q4: 15 | R4: 16 | S4: 17 | T4: 18 | U4: 19 | V4: 20 | W4: 21 | X4: 22 | Y4: 23 | Z4: 24 | AA4: 25 | AB4: 26 | AC4: 27 | AD4: 28 | AE4: 29 | AF4: 30 | AG4: 31 | AH4: 32 | AI4: 33 | AJ4: 34 | AK4: 35 | AL4: 36
A5: Original plan | C5: Original: 4 clients in Year 1 incl. TWK, 7 in Year 2, 9 in Year 3, ignoring the CPA calendar; industrial project revenue calibrated to the source revenue totals
A6: Professional clients signed (excl. TWK) | B6: =SUM(C6:AL6) -> 19 | C6: 0 | D6: 0 | E6: 1 | F6: 0 | G6: 0 | H6: 1 | I6: 0 | J6: 0 | K6: 1 | L6: 0 | M6: 0 | N6: 0 | O6: 1 | P6: 0 | Q6: 1 | R6: 0 | S6: 1 | T6: 0 | U6: 1 | V6: 1 | W6: 0 | X6: 1 | Y6: 1 | Z6: 0 | AA6: 1 | AB6: 1 | AC6: 0 | AD6: 1 | AE6: 1 | AF6: 1 | AG6: 0 | AH6: 1 | AI6: 1 | AJ6: 1 | AK6: 1 | AL6: 0
A7: Contractor compliance clients signed | B7: =SUM(C7:AL7) -> 0 | C7: 0 | D7: 0 | E7: 0 | F7: 0 | G7: 0 | H7: 0 | I7: 0 | J7: 0 | K7: 0 | L7: 0 | M7: 0 | N7: 0 | O7: 0 | P7: 0 | Q7: 0 | R7: 0 | S7: 0 | T7: 0 | U7: 0 | V7: 0 | W7: 0 | X7: 0 | Y7: 0 | Z7: 0 | AA7: 0 | AB7: 0 | AC7: 0 | AD7: 0 | AE7: 0 | AF7: 0 | AG7: 0 | AH7: 0 | AI7: 0 | AJ7: 0 | AK7: 0 | AL7: 0
A8: Industrial project revenue ($) | B8: =SUM(C8:AL8) -> 201138 | C8: 0 | D8: 0 | E8: 0 | F8: 0 | G8: 0 | H8: 0 | I8: 0 | J8: 0 | K8: 0 | L8: 0 | M8: 0 | N8: 0 | O8: 7691.5 | P8: 7691.5 | Q8: 7691.5 | R8: 7691.5 | S8: 7691.5 | T8: 7691.5 | U8: 7691.5 | V8: 7691.5 | W8: 7691.5 | X8: 7691.5 | Y8: 7691.5 | Z8: 7691.5 | AA8: 9070 | AB8: 9070 | AC8: 9070 | AD8: 9070 | AE8: 9070 | AF8: 9070 | AG8: 9070 | AH8: 9070 | AI8: 9070 | AJ8: 9070 | AK8: 9070 | AL8: 9070
A10: Conservative | C10: Conservative per 14-revised-plan
A11: Professional clients signed (excl. TWK) | B11: =SUM(C11:AL11) -> 13 | C11: 0 | D11: 0 | E11: 0 | F11: 0 | G11: 0 | H11: 0 | I11: 1 | J11: 0 | K11: 0 | L11: 1 | M11: 0 | N11: 0 | O11: 1 | P11: 0 | Q11: 0 | R11: 0 | S11: 1 | T11: 0 | U11: 0 | V11: 1 | W11: 0 | X11: 1 | Y11: 0 | Z11: 1 | AA11: 1 | AB11: 0 | AC11: 0 | AD11: 1 | AE11: 0 | AF11: 0 | AG11: 1 | AH11: 0 | AI11: 1 | AJ11: 1 | AK11: 0 | AL11: 1
A12: Contractor compliance clients signed | B12: =SUM(C12:AL12) -> 12 | C12: 0 | D12: 0 | E12: 1 | F12: 0 | G12: 0 | H12: 1 | I12: 0 | J12: 0 | K12: 1 | L12: 0 | M12: 1 | N12: 0 | O12: 0 | P12: 1 | Q12: 0 | R12: 1 | S12: 0 | T12: 1 | U12: 0 | V12: 1 | W12: 0 | X12: 1 | Y12: 0 | Z12: 0 | AA12: 0 | AB12: 1 | AC12: 0 | AD12: 0 | AE12: 0 | AF12: 1 | AG12: 0 | AH12: 0 | AI12: 0 | AJ12: 1 | AK12: 0 | AL12: 0
A13: Industrial project revenue ($) | B13: =SUM(C13:AL13) -> 35000 | C13: 0 | D13: 0 | E13: 0 | F13: 0 | G13: 0 | H13: 0 | I13: 0 | J13: 0 | K13: 0 | L13: 0 | M13: 0 | N13: 0 | O13: 0 | P13: 0 | Q13: 0 | R13: 0 | S13: 0 | T13: 0 | U13: 0 | V13: 15000 | W13: 0 | X13: 0 | Y13: 0 | Z13: 0 | AA13: 0 | AB13: 0 | AC13: 0 | AD13: 0 | AE13: 0 | AF13: 20000 | AG13: 0 | AH13: 0 | AI13: 0 | AJ13: 0 | AK13: 0 | AL13: 0
A15: Base | C15: Base per 14-revised-plan: 3 beyond TWK in Year 1, then 7 and 9 (plan counts)
A16: Professional clients signed (excl. TWK) | B16: =SUM(C16:AL16) -> 19 | C16: 0 | D16: 0 | E16: 0 | F16: 0 | G16: 0 | H16: 1 | I16: 0 | J16: 1 | K16: 0 | L16: 1 | M16: 0 | N16: 0 | O16: 1 | P16: 1 | Q16: 0 | R16: 1 | S16: 0 | T16: 1 | U16: 0 | V16: 1 | W16: 1 | X16: 0 | Y16: 1 | Z16: 0 | AA16: 1 | AB16: 1 | AC16: 0 | AD16: 1 | AE16: 0 | AF16: 1 | AG16: 1 | AH16: 1 | AI16: 1 | AJ16: 1 | AK16: 1 | AL16: 0
A17: Contractor compliance clients signed | B17: =SUM(C17:AL17) -> 18 | C17: 0 | D17: 1 | E17: 1 | F17: 0 | G17: 1 | H17: 0 | I17: 1 | J17: 0 | K17: 1 | L17: 0 | M17: 1 | N17: 0 | O17: 1 | P17: 1 | Q17: 1 | R17: 1 | S17: 1 | T17: 0 | U17: 1 | V17: 0 | W17: 1 | X17: 0 | Y17: 1 | Z17: 0 | AA17: 1 | AB17: 0 | AC17: 1 | AD17: 0 | AE17: 1 | AF17: 0 | AG17: 1 | AH17: 0 | AI17: 0 | AJ17: 0 | AK17: 0 | AL17: 0
A18: Industrial project revenue ($) | B18: =SUM(C18:AL18) -> 69000 | C18: 0 | D18: 0 | E18: 0 | F18: 0 | G18: 0 | H18: 5000 | I18: 0 | J18: 4000 | K18: 0 | L18: 0 | M18: 0 | N18: 0 | O18: 0 | P18: 0 | Q18: 0 | R18: 0 | S18: 0 | T18: 0 | U18: 20000 | V18: 0 | W18: 0 | X18: 0 | Y18: 0 | Z18: 0 | AA18: 0 | AB18: 0 | AC18: 0 | AD18: 20000 | AE18: 0 | AF18: 0 | AG18: 0 | AH18: 0 | AI18: 20000 | AJ18: 0 | AK18: 0 | AL18: 0
A20: Stretch | C20: Stretch per 14-revised-plan
A21: Professional clients signed (excl. TWK) | B21: =SUM(C21:AL21) -> 24 | C21: 0 | D21: 0 | E21: 0 | F21: 0 | G21: 1 | H21: 0 | I21: 0 | J21: 1 | K21: 1 | L21: 1 | M21: 0 | N21: 0 | O21: 1 | P21: 1 | Q21: 1 | R21: 0 | S21: 1 | T21: 0 | U21: 1 | V21: 1 | W21: 1 | X21: 1 | Y21: 1 | Z21: 0 | AA21: 1 | AB21: 1 | AC21: 1 | AD21: 1 | AE21: 1 | AF21: 0 | AG21: 1 | AH21: 1 | AI21: 1 | AJ21: 1 | AK21: 1 | AL21: 1
A22: Contractor compliance clients signed | B22: =SUM(C22:AL22) -> 24 | C22: 0 | D22: 1 | E22: 1 | F22: 1 | G22: 1 | H22: 0 | I22: 1 | J22: 1 | K22: 1 | L22: 0 | M22: 1 | N22: 0 | O22: 1 | P22: 1 | Q22: 1 | R22: 1 | S22: 1 | T22: 1 | U22: 1 | V22: 1 | W22: 1 | X22: 1 | Y22: 0 | Z22: 0 | AA22: 1 | AB22: 0 | AC22: 1 | AD22: 0 | AE22: 1 | AF22: 0 | AG22: 1 | AH22: 0 | AI22: 1 | AJ22: 0 | AK22: 1 | AL22: 0
A23: Industrial project revenue ($) | B23: =SUM(C23:AL23) -> 204000 | C23: 0 | D23: 0 | E23: 0 | F23: 0 | G23: 0 | H23: 5000 | I23: 0 | J23: 4000 | K23: 0 | L23: 20000 | M23: 0 | N23: 0 | O23: 0 | P23: 0 | Q23: 0 | R23: 25000 | S23: 0 | T23: 0 | U23: 20000 | V23: 0 | W23: 0 | X23: 30000 | Y23: 0 | Z23: 0 | AA23: 0 | AB23: 0 | AC23: 30000 | AD23: 0 | AE23: 0 | AF23: 40000 | AG23: 0 | AH23: 0 | AI23: 30000 | AJ23: 0 | AK23: 0 | AL23: 0

Sheet M_Original
A1: Original plan — monthly model (all cells are formulas)
A2: Month | C2: 1 | D2: 2 | E2: 3 | F2: 4 | G2: 5 | H2: 6 | I2: 7 | J2: 8 | K2: 9 | L2: 10 | M2: 11 | N2: 12 | O2: 13 | P2: 14 | Q2: 15 | R2: 16 | S2: 17 | T2: 18 | U2: 19 | V2: 20 | W2: 21 | X2: 22 | Y2: 23 | Z2: 24 | AA2: 25 | AB2: 26 | AC2: 27 | AD2: 28 | AE2: 29 | AF2: 30 | AG2: 31 | AH2: 32 | AI2: 33 | AJ2: 34 | AK2: 35 | AL2: 36
A3: Model year | C3: =ROUNDUP(C2/12,0) -> 1 | D3: =ROUNDUP(D2/12,0) -> 1 | E3: =ROUNDUP(E2/12,0) -> 1 | F3: =ROUNDUP(F2/12,0) -> 1 | G3: =ROUNDUP(G2/12,0) -> 1 | H3: =ROUNDUP(H2/12,0) -> 1 | I3: =ROUNDUP(I2/12,0) -> 1 | J3: =ROUNDUP(J2/12,0) -> 1 | ... AL3: =ROUNDUP(AL2/12,0) -> 3
A4: Month starts | C4: =DATE(2026,10,19)+ROUND((C2-1)*30.44,0) -> 46314 | D4: =DATE(2026,10,19)+ROUND((D2-1)*30.44,0) -> 46344 | E4: =DATE(2026,10,19)+ROUND((E2-1)*30.44,0) -> 46375 | F4: =DATE(2026,10,19)+ROUND((F2-1)*30.44,0) -> 46405 | G4: =DATE(2026,10,19)+ROUND((G2-1)*30.44,0) -> 46436 | H4: =DATE(2026,10,19)+ROUND((H2-1)*30.44,0) -> 46466 | I4: =DATE(2026,10,19)+ROUND((I2-1)*30.44,0) -> 46497 | J4: =DATE(2026,10,19)+ROUND((J2-1)*30.44,0) -> 46527 | ... AL4: =DATE(2026,10,19)+ROUND((AL2-1)*30.44,0) -> 47379
A6: Clients
A7: TWK signed | C7: =IF(C$2=Inputs!$C$6,1,0) -> 1 | D7: =IF(D$2=Inputs!$C$6,1,0) -> 0 | E7: =IF(E$2=Inputs!$C$6,1,0) -> 0 | F7: =IF(F$2=Inputs!$C$6,1,0) -> 0 | G7: =IF(G$2=Inputs!$C$6,1,0) -> 0 | H7: =IF(H$2=Inputs!$C$6,1,0) -> 0 | I7: =IF(I$2=Inputs!$C$6,1,0) -> 0 | J7: =IF(J$2=Inputs!$C$6,1,0) -> 0 | ... AL7: =IF(AL$2=Inputs!$C$6,1,0) -> 0
A8: Professional clients signed (excl. TWK) | C8: =Schedules!C6 -> 0 | D8: =Schedules!D6 -> 0 | E8: =Schedules!E6 -> 1 | F8: =Schedules!F6 -> 0 | G8: =Schedules!G6 -> 0 | H8: =Schedules!H6 -> 1 | I8: =Schedules!I6 -> 0 | J8: =Schedules!J6 -> 0 | ... AL8: =Schedules!AL6 -> 0
A9: Professional clients accepted (excl. TWK) | C9: =IF(C$2-Inputs!$C$12>=1,INDEX($C$8:$AL$8,C$2-Inputs!$C$12),0) -> 0 | D9: =IF(D$2-Inputs!$C$12>=1,INDEX($C$8:$AL$8,D$2-Inputs!$C$12),0) -> 0 | E9: =IF(E$2-Inputs!$C$12>=1,INDEX($C$8:$AL$8,E$2-Inputs!$C$12),0) -> 0 | F9: =IF(F$2-Inputs!$C$12>=1,INDEX($C$8:$AL$8,F$2-Inputs!$C$12),0) -> 0 | G9: =IF(G$2-Inputs!$C$12>=1,INDEX($C$8:$AL$8,G$2-Inputs!$C$12),0) -> 1 | H9: =IF(H$2-Inputs!$C$12>=1,INDEX($C$8:$AL$8,H$2-Inputs!$C$12),0) -> 0 | I9: =IF(I$2-Inputs!$C$12>=1,INDEX($C$8:$AL$8,I$2-Inputs!$C$12),0) -> 0 | J9: =IF(J$2-Inputs!$C$12>=1,INDEX($C$8:$AL$8,J$2-Inputs!$C$12),0) -> 1 | ... AL9: =IF(AL$2-Inputs!$C$12>=1,INDEX($C$8:$AL$8,AL$2-Inputs!$C$12),0) -> 1
A10: TWK accepted | C10: =IF(C$2=Inputs!$C$6+Inputs!$C$12,1,0) -> 0 | D10: =IF(D$2=Inputs!$C$6+Inputs!$C$12,1,0) -> 0 | E10: =IF(E$2=Inputs!$C$6+Inputs!$C$12,1,0) -> 1 | F10: =IF(F$2=Inputs!$C$6+Inputs!$C$12,1,0) -> 0 | G10: =IF(G$2=Inputs!$C$6+Inputs!$C$12,1,0) -> 0 | H10: =IF(H$2=Inputs!$C$6+Inputs!$C$12,1,0) -> 0 | I10: =IF(I$2=Inputs!$C$6+Inputs!$C$12,1,0) -> 0 | J10: =IF(J$2=Inputs!$C$6+Inputs!$C$12,1,0) -> 0 | ... AL10: =IF(AL$2=Inputs!$C$6+Inputs!$C$12,1,0) -> 0
A11: Cumulative accepted (incl. TWK) | C11: =0+C9+C10 -> 0 | D11: =C11+D9+D10 -> 0 | E11: =D11+E9+E10 -> 1 | F11: =E11+F9+F10 -> 1 | G11: =F11+G9+G10 -> 2 | H11: =G11+H9+H10 -> 2 | I11: =H11+I9+I10 -> 2 | J11: =I11+J9+J10 -> 3 | K11: =J11+K9+K10 -> 3 | ... AL11: =AK11+AL9+AL10 -> 19
A12: Subscribing clients (excl. TWK) | C12: =0+0 -> 0 | D12: =C12+C9 -> 0 | E12: =D12+D9 -> 0 | F12: =E12+E9 -> 0 | G12: =F12+F9 -> 0 | H12: =G12+G9 -> 1 | I12: =H12+H9 -> 1 | J12: =I12+I9 -> 1 | K12: =J12+J9 -> 2 | ... AL12: =AK12+AK9 -> 17
A13: TWK subscribing | C13: =IF(C$2>Inputs!$C$6+Inputs!$C$12,1,0) -> 0 | D13: =IF(D$2>Inputs!$C$6+Inputs!$C$12,1,0) -> 0 | E13: =IF(E$2>Inputs!$C$6+Inputs!$C$12,1,0) -> 0 | F13: =IF(F$2>Inputs!$C$6+Inputs!$C$12,1,0) -> 1 | G13: =IF(G$2>Inputs!$C$6+Inputs!$C$12,1,0) -> 1 | H13: =IF(H$2>Inputs!$C$6+Inputs!$C$12,1,0) -> 1 | I13: =IF(I$2>Inputs!$C$6+Inputs!$C$12,1,0) -> 1 | J13: =IF(J$2>Inputs!$C$6+Inputs!$C$12,1,0) -> 1 | ... AL13: =IF(AL$2>Inputs!$C$6+Inputs!$C$12,1,0) -> 1
A14: Clients eligible for add-ons | C14: =IF(C$2-Inputs!$C$16>=1,INDEX($C$11:$AL$11,C$2-Inputs!$C$16),0) -> 0 | D14: =IF(D$2-Inputs!$C$16>=1,INDEX($C$11:$AL$11,D$2-Inputs!$C$16),0) -> 0 | E14: =IF(E$2-Inputs!$C$16>=1,INDEX($C$11:$AL$11,E$2-Inputs!$C$16),0) -> 0 | F14: =IF(F$2-Inputs!$C$16>=1,INDEX($C$11:$AL$11,F$2-Inputs!$C$16),0) -> 0 | G14: =IF(G$2-Inputs!$C$16>=1,INDEX($C$11:$AL$11,G$2-Inputs!$C$16),0) -> 0 | H14: =IF(H$2-Inputs!$C$16>=1,INDEX($C$11:$AL$11,H$2-Inputs!$C$16),0) -> 1 | I14: =IF(I$2-Inputs!$C$16>=1,INDEX($C$11:$AL$11,I$2-Inputs!$C$16),0) -> 1 | J14: =IF(J$2-Inputs!$C$16>=1,INDEX($C$11:$AL$11,J$2-Inputs!$C$16),0) -> 2 | ... AL14: =IF(AL$2-Inputs!$C$16>=1,INDEX($C$11:$AL$11,AL$2-Inputs!$C$16),0) -> 16
A15: Compliance clients signed | C15: =Schedules!C7 -> 0 | D15: =Schedules!D7 -> 0 | E15: =Schedules!E7 -> 0 | F15: =Schedules!F7 -> 0 | G15: =Schedules!G7 -> 0 | H15: =Schedules!H7 -> 0 | I15: =Schedules!I7 -> 0 | J15: =Schedules!J7 -> 0 | ... AL15: =Schedules!AL7 -> 0
A16: Compliance clients on retainer | C16: =0+0 -> 0 | D16: =C16+C15 -> 0 | E16: =D16+D15 -> 0 | F16: =E16+E15 -> 0 | G16: =F16+F15 -> 0 | H16: =G16+G15 -> 0 | I16: =H16+H15 -> 0 | J16: =I16+I15 -> 0 | K16: =J16+J15 -> 0 | ... AL16: =AK16+AK15 -> 0
A17: Revenue ($)
A18: Escalator factor | C18: =(1+Inputs!$C$13)^(C$3-1) -> 1 | D18: =(1+Inputs!$C$13)^(D$3-1) -> 1 | E18: =(1+Inputs!$C$13)^(E$3-1) -> 1 | F18: =(1+Inputs!$C$13)^(F$3-1) -> 1 | G18: =(1+Inputs!$C$13)^(G$3-1) -> 1 | H18: =(1+Inputs!$C$13)^(H$3-1) -> 1 | I18: =(1+Inputs!$C$13)^(I$3-1) -> 1 | J18: =(1+Inputs!$C$13)^(J$3-1) -> 1 | ... AL18: =(1+Inputs!$C$13)^(AL$3-1) -> 1.1025
A19: Subscriptions | C19: =(C12*Inputs!$C$10+C13*Inputs!$C$8)*C18 -> 0 | D19: =(D12*Inputs!$C$10+D13*Inputs!$C$8)*D18 -> 0 | E19: =(E12*Inputs!$C$10+E13*Inputs!$C$8)*E18 -> 0 | F19: =(F12*Inputs!$C$10+F13*Inputs!$C$8)*F18 -> 3800 | G19: =(G12*Inputs!$C$10+G13*Inputs!$C$8)*G18 -> 3800 | H19: =(H12*Inputs!$C$10+H13*Inputs!$C$8)*H18 -> 6290 | I19: =(I12*Inputs!$C$10+I13*Inputs!$C$8)*I18 -> 6290 | J19: =(J12*Inputs!$C$10+J13*Inputs!$C$8)*J18 -> 6290 | ... AL19: =(AL12*Inputs!$C$10+AL13*Inputs!$C$8)*AL18 -> 50858.325
A20: Workflow add-ons | C20: =C14*Inputs!$C$14*Inputs!$C$15*C18 -> 0 | D20: =D14*Inputs!$C$14*Inputs!$C$15*D18 -> 0 | E20: =E14*Inputs!$C$14*Inputs!$C$15*E18 -> 0 | F20: =F14*Inputs!$C$14*Inputs!$C$15*F18 -> 0 | G20: =G14*Inputs!$C$14*Inputs!$C$15*G18 -> 0 | H20: =H14*Inputs!$C$14*Inputs!$C$15*H18 -> 523.5 | I20: =I14*Inputs!$C$14*Inputs!$C$15*I18 -> 523.5 | J20: =J14*Inputs!$C$14*Inputs!$C$15*J18 -> 1047 | ... AL20: =AL14*Inputs!$C$14*Inputs!$C$15*AL18 -> 9234.54
A21: Setup and implementation | C21: =C8*Inputs!$C$9*Inputs!$C$11+C9*Inputs!$C$9*(1-Inputs!$C$11)+C7*Inputs!$C$7*Inputs!$C$11+C10*Inputs!$C$7*(1-Inputs!$C$11) -> 0 | D21: =D8*Inputs!$C$9*Inputs!$C$11+D9*Inputs!$C$9*(1-Inputs!$C$11)+D7*Inputs!$C$7*Inputs!$C$11+D10*Inputs!$C$7*(1-Inputs!$C$11) -> 0 | E21: =E8*Inputs!$C$9*Inputs!$C$11+E9*Inputs!$C$9*(1-Inputs!$C$11)+E7*Inputs!$C$7*Inputs!$C$11+E10*Inputs!$C$7*(1-Inputs!$C$11) -> 20000 | F21: =F8*Inputs!$C$9*Inputs!$C$11+F9*Inputs!$C$9*(1-Inputs!$C$11)+F7*Inputs!$C$7*Inputs!$C$11+F10*Inputs!$C$7*(1-Inputs!$C$11) -> 0 | G21: =G8*Inputs!$C$9*Inputs!$C$11+G9*Inputs!$C$9*(1-Inputs!$C$11)+G7*Inputs!$C$7*Inputs!$C$11+G10*Inputs!$C$7*(1-Inputs!$C$11) -> 19111 | H21: =H8*Inputs!$C$9*Inputs!$C$11+H9*Inputs!$C$9*(1-Inputs!$C$11)+H7*Inputs!$C$7*Inputs!$C$11+H10*Inputs!$C$7*(1-Inputs!$C$11) -> 0 | I21: =I8*Inputs!$C$9*Inputs!$C$11+I9*Inputs!$C$9*(1-Inputs!$C$11)+I7*Inputs!$C$7*Inputs!$C$11+I10*Inputs!$C$7*(1-Inputs!$C$11) -> 0 | J21: =J8*Inputs!$C$9*Inputs!$C$11+J9*Inputs!$C$9*(1-Inputs!$C$11)+J7*Inputs!$C$7*Inputs!$C$11+J10*Inputs!$C$7*(1-Inputs!$C$11) -> 19111 | ... AL21: =AL8*Inputs!$C$9*Inputs!$C$11+AL9*Inputs!$C$9*(1-Inputs!$C$11)+AL7*Inputs!$C$7*Inputs!$C$11+AL10*Inputs!$C$7*(1-Inputs!$C$11) -> 19111
A22: Hardware margin | C22: =(C9+C10)*Inputs!$C$17*Inputs!$C$18 -> 0 | D22: =(D9+D10)*Inputs!$C$17*Inputs!$C$18 -> 0 | E22: =(E9+E10)*Inputs!$C$17*Inputs!$C$18 -> 2240 | F22: =(F9+F10)*Inputs!$C$17*Inputs!$C$18 -> 0 | G22: =(G9+G10)*Inputs!$C$17*Inputs!$C$18 -> 2240 | H22: =(H9+H10)*Inputs!$C$17*Inputs!$C$18 -> 0 | I22: =(I9+I10)*Inputs!$C$17*Inputs!$C$18 -> 0 | J22: =(J9+J10)*Inputs!$C$17*Inputs!$C$18 -> 2240 | ... AL22: =(AL9+AL10)*Inputs!$C$17*Inputs!$C$18 -> 2240
A23: Contractor compliance | C23: =C15*Inputs!$C$20+C16*Inputs!$C$21 -> 0 | D23: =D15*Inputs!$C$20+D16*Inputs!$C$21 -> 0 | E23: =E15*Inputs!$C$20+E16*Inputs!$C$21 -> 0 | F23: =F15*Inputs!$C$20+F16*Inputs!$C$21 -> 0 | G23: =G15*Inputs!$C$20+G16*Inputs!$C$21 -> 0 | H23: =H15*Inputs!$C$20+H16*Inputs!$C$21 -> 0 | I23: =I15*Inputs!$C$20+I16*Inputs!$C$21 -> 0 | J23: =J15*Inputs!$C$20+J16*Inputs!$C$21 -> 0 | ... AL23: =AL15*Inputs!$C$20+AL16*Inputs!$C$21 -> 0
A24: Industrial projects | C24: =Schedules!C8 -> 0 | D24: =Schedules!D8 -> 0 | E24: =Schedules!E8 -> 0 | F24: =Schedules!F8 -> 0 | G24: =Schedules!G8 -> 0 | H24: =Schedules!H8 -> 0 | I24: =Schedules!I8 -> 0 | J24: =Schedules!J8 -> 0 | ... AL24: =Schedules!AL8 -> 9070
A25: Total revenue | C25: =SUM(C19:C24) -> 0 | D25: =SUM(D19:D24) -> 0 | E25: =SUM(E19:E24) -> 22240 | F25: =SUM(F19:F24) -> 3800 | G25: =SUM(G19:G24) -> 25151 | H25: =SUM(H19:H24) -> 6813.5 | I25: =SUM(I19:I24) -> 6813.5 | J25: =SUM(J19:J24) -> 28688 | ... AL25: =SUM(AL19:AL24) -> 90513.865
A26: MRR (subscriptions + add-ons + retainers) | C26: =C19+C20+C16*Inputs!$C$21 -> 0 | D26: =D19+D20+D16*Inputs!$C$21 -> 0 | E26: =E19+E20+E16*Inputs!$C$21 -> 0 | F26: =F19+F20+F16*Inputs!$C$21 -> 3800 | G26: =G19+G20+G16*Inputs!$C$21 -> 3800 | H26: =H19+H20+H16*Inputs!$C$21 -> 6813.5 | I26: =I19+I20+I16*Inputs!$C$21 -> 6813.5 | J26: =J19+J20+J16*Inputs!$C$21 -> 7337 | ... AL26: =AL19+AL20+AL16*Inputs!$C$21 -> 60092.865
A27: Gross profit ($)
A28: Cost of revenue | C28: =C21*(1-Inputs!$C$23)+C19*(1-Inputs!$C$24)+C20*(1-Inputs!$C$25)+C22*(1-Inputs!$C$26)+C23*(1-Inputs!$C$27)+C24*(1-Inputs!$C$28) -> 0 | D28: =D21*(1-Inputs!$C$23)+D19*(1-Inputs!$C$24)+D20*(1-Inputs!$C$25)+D22*(1-Inputs!$C$26)+D23*(1-Inputs!$C$27)+D24*(1-Inputs!$C$28) -> 0 | E28: =E21*(1-Inputs!$C$23)+E19*(1-Inputs!$C$24)+E20*(1-Inputs!$C$25)+E22*(1-Inputs!$C$26)+E23*(1-Inputs!$C$27)+E24*(1-Inputs!$C$28) -> 9000 | F28: =F21*(1-Inputs!$C$23)+F19*(1-Inputs!$C$24)+F20*(1-Inputs!$C$25)+F22*(1-Inputs!$C$26)+F23*(1-Inputs!$C$27)+F24*(1-Inputs!$C$28) -> 1140 | G28: =G21*(1-Inputs!$C$23)+G19*(1-Inputs!$C$24)+G20*(1-Inputs!$C$25)+G22*(1-Inputs!$C$26)+G23*(1-Inputs!$C$27)+G24*(1-Inputs!$C$28) -> 9739.95 | H28: =H21*(1-Inputs!$C$23)+H19*(1-Inputs!$C$24)+H20*(1-Inputs!$C$25)+H22*(1-Inputs!$C$26)+H23*(1-Inputs!$C$27)+H24*(1-Inputs!$C$28) -> 1965.525 | I28: =I21*(1-Inputs!$C$23)+I19*(1-Inputs!$C$24)+I20*(1-Inputs!$C$25)+I22*(1-Inputs!$C$26)+I23*(1-Inputs!$C$27)+I24*(1-Inputs!$C$28) -> 1965.525 | J28: =J21*(1-Inputs!$C$23)+J19*(1-Inputs!$C$24)+J20*(1-Inputs!$C$25)+J22*(1-Inputs!$C$26)+J23*(1-Inputs!$C$27)+J24*(1-Inputs!$C$28) -> 10644 | ... AL28: =AL21*(1-Inputs!$C$23)+AL19*(1-Inputs!$C$24)+AL20*(1-Inputs!$C$25)+AL22*(1-Inputs!$C$26)+AL23*(1-Inputs!$C$27)+AL24*(1-Inputs!$C$28) -> 28417.128
A29: Gross profit | C29: =C25-C28 -> 0 | D29: =D25-D28 -> 0 | E29: =E25-E28 -> 13240 | F29: =F25-F28 -> 2660 | G29: =G25-G28 -> 15411.05 | H29: =H25-H28 -> 4847.975 | I29: =I25-I28 -> 4847.975 | J29: =J25-J28 -> 18044 | ... AL29: =AL25-AL28 -> 62096.736
A30: Operating costs ($)
A31: Founder salary | C31: =CHOOSE(C$3,Inputs!$C$30,Inputs!$C$31,Inputs!$C$32)/12 -> 5833.3333 | D31: =CHOOSE(D$3,Inputs!$C$30,Inputs!$C$31,Inputs!$C$32)/12 -> 5833.3333 | E31: =CHOOSE(E$3,Inputs!$C$30,Inputs!$C$31,Inputs!$C$32)/12 -> 5833.3333 | F31: =CHOOSE(F$3,Inputs!$C$30,Inputs!$C$31,Inputs!$C$32)/12 -> 5833.3333 | G31: =CHOOSE(G$3,Inputs!$C$30,Inputs!$C$31,Inputs!$C$32)/12 -> 5833.3333 | H31: =CHOOSE(H$3,Inputs!$C$30,Inputs!$C$31,Inputs!$C$32)/12 -> 5833.3333 | I31: =CHOOSE(I$3,Inputs!$C$30,Inputs!$C$31,Inputs!$C$32)/12 -> 5833.3333 | J31: =CHOOSE(J$3,Inputs!$C$30,Inputs!$C$31,Inputs!$C$32)/12 -> 5833.3333 | ... AL31: =CHOOSE(AL$3,Inputs!$C$30,Inputs!$C$31,Inputs!$C$32)/12 -> 10833.333
A32: Employer payroll taxes (founder) | C32: =C31*Inputs!$C$33 -> 446.25 | D32: =D31*Inputs!$C$33 -> 446.25 | E32: =E31*Inputs!$C$33 -> 446.25 | F32: =F31*Inputs!$C$33 -> 446.25 | G32: =G31*Inputs!$C$33 -> 446.25 | H32: =H31*Inputs!$C$33 -> 446.25 | I32: =I31*Inputs!$C$33 -> 446.25 | J32: =J31*Inputs!$C$33 -> 446.25 | ... AL32: =AL31*Inputs!$C$33 -> 828.75
A33: Staff (loaded) | C33: =IF(C$2>=Inputs!$C$34,Inputs!$C$35/12,0)+IF(C$2>=Inputs!$C$36,Inputs!$C$37/12,0) -> 0 | D33: =IF(D$2>=Inputs!$C$34,Inputs!$C$35/12,0)+IF(D$2>=Inputs!$C$36,Inputs!$C$37/12,0) -> 0 | E33: =IF(E$2>=Inputs!$C$34,Inputs!$C$35/12,0)+IF(E$2>=Inputs!$C$36,Inputs!$C$37/12,0) -> 0 | F33: =IF(F$2>=Inputs!$C$34,Inputs!$C$35/12,0)+IF(F$2>=Inputs!$C$36,Inputs!$C$37/12,0) -> 0 | G33: =IF(G$2>=Inputs!$C$34,Inputs!$C$35/12,0)+IF(G$2>=Inputs!$C$36,Inputs!$C$37/12,0) -> 0 | H33: =IF(H$2>=Inputs!$C$34,Inputs!$C$35/12,0)+IF(H$2>=Inputs!$C$36,Inputs!$C$37/12,0) -> 0 | I33: =IF(I$2>=Inputs!$C$34,Inputs!$C$35/12,0)+IF(I$2>=Inputs!$C$36,Inputs!$C$37/12,0) -> 0 | J33: =IF(J$2>=Inputs!$C$34,Inputs!$C$35/12,0)+IF(J$2>=Inputs!$C$36,Inputs!$C$37/12,0) -> 0 | ... AL33: =IF(AL$2>=Inputs!$C$34,Inputs!$C$35/12,0)+IF(AL$2>=Inputs!$C$36,Inputs!$C$37/12,0) -> 15000
A34: Contract engineer + student | C34: =IF(AND(C$2>=Inputs!$C$38,C$2<Inputs!$C$34),Inputs!$C$39+Inputs!$C$40,0) -> 0 | D34: =IF(AND(D$2>=Inputs!$C$38,D$2<Inputs!$C$34),Inputs!$C$39+Inputs!$C$40,0) -> 0 | E34: =IF(AND(E$2>=Inputs!$C$38,E$2<Inputs!$C$34),Inputs!$C$39+Inputs!$C$40,0) -> 0 | F34: =IF(AND(F$2>=Inputs!$C$38,F$2<Inputs!$C$34),Inputs!$C$39+Inputs!$C$40,0) -> 0 | G34: =IF(AND(G$2>=Inputs!$C$38,G$2<Inputs!$C$34),Inputs!$C$39+Inputs!$C$40,0) -> 0 | H34: =IF(AND(H$2>=Inputs!$C$38,H$2<Inputs!$C$34),Inputs!$C$39+Inputs!$C$40,0) -> 0 | I34: =IF(AND(I$2>=Inputs!$C$38,I$2<Inputs!$C$34),Inputs!$C$39+Inputs!$C$40,0) -> 0 | J34: =IF(AND(J$2>=Inputs!$C$38,J$2<Inputs!$C$34),Inputs!$C$39+Inputs!$C$40,0) -> 0 | ... AL34: =IF(AND(AL$2>=Inputs!$C$38,AL$2<Inputs!$C$34),Inputs!$C$39+Inputs!$C$40,0) -> 0
A35: Memberships, events, travel | C35: =Inputs!$C$42/12 -> 2083.3333 | D35: =Inputs!$C$42/12 -> 2083.3333 | E35: =Inputs!$C$42/12 -> 2083.3333 | F35: =Inputs!$C$42/12 -> 2083.3333 | G35: =Inputs!$C$42/12 -> 2083.3333 | H35: =Inputs!$C$42/12 -> 2083.3333 | I35: =Inputs!$C$42/12 -> 2083.3333 | J35: =Inputs!$C$42/12 -> 2083.3333 | ... AL35: =Inputs!$C$42/12 -> 2083.3333
A36: Insurance (incl. key-person) | C36: =(Inputs!$C$43+Inputs!$C$44)/12 -> 666.66667 | D36: =(Inputs!$C$43+Inputs!$C$44)/12 -> 666.66667 | E36: =(Inputs!$C$43+Inputs!$C$44)/12 -> 666.66667 | F36: =(Inputs!$C$43+Inputs!$C$44)/12 -> 666.66667 | G36: =(Inputs!$C$43+Inputs!$C$44)/12 -> 666.66667 | H36: =(Inputs!$C$43+Inputs!$C$44)/12 -> 666.66667 | I36: =(Inputs!$C$43+Inputs!$C$44)/12 -> 666.66667 | J36: =(Inputs!$C$43+Inputs!$C$44)/12 -> 666.66667 | ... AL36: =(Inputs!$C$43+Inputs!$C$44)/12 -> 666.66667
A37: Software, tools, hosting | C37: =Inputs!$C$45 -> 1000 | D37: =Inputs!$C$45 -> 1000 | E37: =Inputs!$C$45 -> 1000 | F37: =Inputs!$C$45 -> 1000 | G37: =Inputs!$C$45 -> 1000 | H37: =Inputs!$C$45 -> 1000 | I37: =Inputs!$C$45 -> 1000 | J37: =Inputs!$C$45 -> 1000 | ... AL37: =Inputs!$C$45 -> 1000
A38: Professional fees + formation | C38: =Inputs!$C$46+IF(C$2<=3,Inputs!$C$47/3,0) -> 5000 | D38: =Inputs!$C$46+IF(D$2<=3,Inputs!$C$47/3,0) -> 5000 | E38: =Inputs!$C$46+IF(E$2<=3,Inputs!$C$47/3,0) -> 5000 | F38: =Inputs!$C$46+IF(F$2<=3,Inputs!$C$47/3,0) -> 1000 | G38: =Inputs!$C$46+IF(G$2<=3,Inputs!$C$47/3,0) -> 1000 | H38: =Inputs!$C$46+IF(H$2<=3,Inputs!$C$47/3,0) -> 1000 | I38: =Inputs!$C$46+IF(I$2<=3,Inputs!$C$47/3,0) -> 1000 | J38: =Inputs!$C$46+IF(J$2<=3,Inputs!$C$47/3,0) -> 1000 | ... AL38: =Inputs!$C$46+IF(AL$2<=3,Inputs!$C$47/3,0) -> 1000
A39: Unitemized (calibrated) | C39: =CHOOSE(C$3,Inputs!$C$48,Inputs!$C$49,Inputs!$C$50)/12 -> 2716.5833 | D39: =CHOOSE(D$3,Inputs!$C$48,Inputs!$C$49,Inputs!$C$50)/12 -> 2716.5833 | E39: =CHOOSE(E$3,Inputs!$C$48,Inputs!$C$49,Inputs!$C$50)/12 -> 2716.5833 | F39: =CHOOSE(F$3,Inputs!$C$48,Inputs!$C$49,Inputs!$C$50)/12 -> 2716.5833 | G39: =CHOOSE(G$3,Inputs!$C$48,Inputs!$C$49,Inputs!$C$50)/12 -> 2716.5833 | H39: =CHOOSE(H$3,Inputs!$C$48,Inputs!$C$49,Inputs!$C$50)/12 -> 2716.5833 | I39: =CHOOSE(I$3,Inputs!$C$48,Inputs!$C$49,Inputs!$C$50)/12 -> 2716.5833 | J39: =CHOOSE(J$3,Inputs!$C$48,Inputs!$C$49,Inputs!$C$50)/12 -> 2716.5833 | ... AL39: =CHOOSE(AL$3,Inputs!$C$48,Inputs!$C$49,Inputs!$C$50)/12 -> 4815.4167
A40: Total operating costs | C40: =SUM(C31:C39) -> 17746.167 | D40: =SUM(D31:D39) -> 17746.167 | E40: =SUM(E31:E39) -> 17746.167 | F40: =SUM(F31:F39) -> 13746.167 | G40: =SUM(G31:G39) -> 13746.167 | H40: =SUM(H31:H39) -> 13746.167 | I40: =SUM(I31:I39) -> 13746.167 | J40: =SUM(J31:J39) -> 13746.167 | ... AL40: =SUM(AL31:AL39) -> 36227.5
A41: Operating result | C41: =C29-C40 -> -17746.167 | D41: =D29-D40 -> -17746.167 | E41: =E29-E40 -> -4506.1667 | F41: =F29-F40 -> -11086.167 | G41: =G29-G40 -> 1664.8833 | H41: =H29-H40 -> -8898.1917 | I41: =I29-I40 -> -8898.1917 | J41: =J29-J40 -> 4297.8333 | ... AL41: =AL29-AL40 -> 25869.236
...

Sheet M_Conservative
A1: Conservative — monthly model (all cells are formulas)
A2: Month | C2: 1 | D2: 2 | E2: 3 | F2: 4 | G2: 5 | H2: 6 | I2: 7 | J2: 8 | K2: 9 | L2: 10 | M2: 11 | N2: 12 | O2: 13 | P2: 14 | Q2: 15 | R2: 16 | S2: 17 | T2: 18 | U2: 19 | V2: 20 | W2: 21 | X2: 22 | Y2: 23 | Z2: 24 | AA2: 25 | AB2: 26 | AC2: 27 | AD2: 28 | AE2: 29 | AF2: 30 | AG2: 31 | AH2: 32 | AI2: 33 | AJ2: 34 | AK2: 35 | AL2: 36
A3: Model year | C3: =ROUNDUP(C2/12,0) -> 1 | D3: =ROUNDUP(D2/12,0) -> 1 | E3: =ROUNDUP(E2/12,0) -> 1 | F3: =ROUNDUP(F2/12,0) -> 1 | G3: =ROUNDUP(G2/12,0) -> 1 | H3: =ROUNDUP(H2/12,0) -> 1 | I3: =ROUNDUP(I2/12,0) -> 1 | J3: =ROUNDUP(J2/12,0) -> 1 | ... AL3: =ROUNDUP(AL2/12,0) -> 3
A4: Month starts | C4: =DATE(2026,10,19)+ROUND((C2-1)*30.44,0) -> 46314 | D4: =DATE(2026,10,19)+ROUND((D2-1)*30.44,0) -> 46344 | E4: =DATE(2026,10,19)+ROUND((E2-1)*30.44,0) -> 46375 | F4: =DATE(2026,10,19)+ROUND((F2-1)*30.44,0) -> 46405 | G4: =DATE(2026,10,19)+ROUND((G2-1)*30.44,0) -> 46436 | H4: =DATE(2026,10,19)+ROUND((H2-1)*30.44,0) -> 46466 | I4: =DATE(2026,10,19)+ROUND((I2-1)*30.44,0) -> 46497 | J4: =DATE(2026,10,19)+ROUND((J2-1)*30.44,0) -> 46527 | ... AL4: =DATE(2026,10,19)+ROUND((AL2-1)*30.44,0) -> 47379
A6: Clients
A7: TWK signed | C7: =IF(C$2=Inputs!$D$6,1,0) -> 1 | D7: =IF(D$2=Inputs!$D$6,1,0) -> 0 | E7: =IF(E$2=Inputs!$D$6,1,0) -> 0 | F7: =IF(F$2=Inputs!$D$6,1,0) -> 0 | G7: =IF(G$2=Inputs!$D$6,1,0) -> 0 | H7: =IF(H$2=Inputs!$D$6,1,0) -> 0 | I7: =IF(I$2=Inputs!$D$6,1,0) -> 0 | J7: =IF(J$2=Inputs!$D$6,1,0) -> 0 | ... AL7: =IF(AL$2=Inputs!$D$6,1,0) -> 0
A8: Professional clients signed (excl. TWK) | C8: =Schedules!C11 -> 0 | D8: =Schedules!D11 -> 0 | E8: =Schedules!E11 -> 0 | F8: =Schedules!F11 -> 0 | G8: =Schedules!G11 -> 0 | H8: =Schedules!H11 -> 0 | I8: =Schedules!I11 -> 1 | J8: =Schedules!J11 -> 0 | ... AL8: =Schedules!AL11 -> 1
A9: Professional clients accepted (excl. TWK) | C9: =IF(C$2-Inputs!$D$12>=1,INDEX($C$8:$AL$8,C$2-Inputs!$D$12),0) -> 0 | D9: =IF(D$2-Inputs!$D$12>=1,INDEX($C$8:$AL$8,D$2-Inputs!$D$12),0) -> 0 | E9: =IF(E$2-Inputs!$D$12>=1,INDEX($C$8:$AL$8,E$2-Inputs!$D$12),0) -> 0 | F9: =IF(F$2-Inputs!$D$12>=1,INDEX($C$8:$AL$8,F$2-Inputs!$D$12),0) -> 0 | G9: =IF(G$2-Inputs!$D$12>=1,INDEX($C$8:$AL$8,G$2-Inputs!$D$12),0) -> 0 | H9: =IF(H$2-Inputs!$D$12>=1,INDEX($C$8:$AL$8,H$2-Inputs!$D$12),0) -> 0 | I9: =IF(I$2-Inputs!$D$12>=1,INDEX($C$8:$AL$8,I$2-Inputs!$D$12),0) -> 0 | J9: =IF(J$2-Inputs!$D$12>=1,INDEX($C$8:$AL$8,J$2-Inputs!$D$12),0) -> 0 | ... AL9: =IF(AL$2-Inputs!$D$12>=1,INDEX($C$8:$AL$8,AL$2-Inputs!$D$12),0) -> 1
A10: TWK accepted | C10: =IF(C$2=Inputs!$D$6+Inputs!$D$12,1,0) -> 0 | D10: =IF(D$2=Inputs!$D$6+Inputs!$D$12,1,0) -> 0 | E10: =IF(E$2=Inputs!$D$6+Inputs!$D$12,1,0) -> 1 | F10: =IF(F$2=Inputs!$D$6+Inputs!$D$12,1,0) -> 0 | G10: =IF(G$2=Inputs!$D$6+Inputs!$D$12,1,0) -> 0 | H10: =IF(H$2=Inputs!$D$6+Inputs!$D$12,1,0) -> 0 | I10: =IF(I$2=Inputs!$D$6+Inputs!$D$12,1,0) -> 0 | J10: =IF(J$2=Inputs!$D$6+Inputs!$D$12,1,0) -> 0 | ... AL10: =IF(AL$2=Inputs!$D$6+Inputs!$D$12,1,0) -> 0
A11: Cumulative accepted (incl. TWK) | C11: =0+C9+C10 -> 0 | D11: =C11+D9+D10 -> 0 | E11: =D11+E9+E10 -> 1 | F11: =E11+F9+F10 -> 1 | G11: =F11+G9+G10 -> 1 | H11: =G11+H9+H10 -> 1 | I11: =H11+I9+I10 -> 1 | J11: =I11+J9+J10 -> 1 | K11: =J11+K9+K10 -> 2 | ... AL11: =AK11+AL9+AL10 -> 13
A12: Subscribing clients (excl. TWK) | C12: =0+0 -> 0 | D12: =C12+C9 -> 0 | E12: =D12+D9 -> 0 | F12: =E12+E9 -> 0 | G12: =F12+F9 -> 0 | H12: =G12+G9 -> 0 | I12: =H12+H9 -> 0 | J12: =I12+I9 -> 0 | K12: =J12+J9 -> 0 | ... AL12: =AK12+AK9 -> 11
A13: TWK subscribing | C13: =IF(C$2>Inputs!$D$6+Inputs!$D$12,1,0) -> 0 | D13: =IF(D$2>Inputs!$D$6+Inputs!$D$12,1,0) -> 0 | E13: =IF(E$2>Inputs!$D$6+Inputs!$D$12,1,0) -> 0 | F13: =IF(F$2>Inputs!$D$6+Inputs!$D$12,1,0) -> 1 | G13: =IF(G$2>Inputs!$D$6+Inputs!$D$12,1,0) -> 1 | H13: =IF(H$2>Inputs!$D$6+Inputs!$D$12,1,0) -> 1 | I13: =IF(I$2>Inputs!$D$6+Inputs!$D$12,1,0) -> 1 | J13: =IF(J$2>Inputs!$D$6+Inputs!$D$12,1,0) -> 1 | ... AL13: =IF(AL$2>Inputs!$D$6+Inputs!$D$12,1,0) -> 1
A14: Clients eligible for add-ons | C14: =IF(C$2-Inputs!$D$16>=1,INDEX($C$11:$AL$11,C$2-Inputs!$D$16),0) -> 0 | D14: =IF(D$2-Inputs!$D$16>=1,INDEX($C$11:$AL$11,D$2-Inputs!$D$16),0) -> 0 | E14: =IF(E$2-Inputs!$D$16>=1,INDEX($C$11:$AL$11,E$2-Inputs!$D$16),0) -> 0 | F14: =IF(F$2-Inputs!$D$16>=1,INDEX($C$11:$AL$11,F$2-Inputs!$D$16),0) -> 0 | G14: =IF(G$2-Inputs!$D$16>=1,INDEX($C$11:$AL$11,G$2-Inputs!$D$16),0) -> 0 | H14: =IF(H$2-Inputs!$D$16>=1,INDEX($C$11:$AL$11,H$2-Inputs!$D$16),0) -> 1 | I14: =IF(I$2-Inputs!$D$16>=1,INDEX($C$11:$AL$11,I$2-Inputs!$D$16),0) -> 1 | J14: =IF(J$2-Inputs!$D$16>=1,INDEX($C$11:$AL$11,J$2-Inputs!$D$16),0) -> 1 | ... AL14: =IF(AL$2-Inputs!$D$16>=1,INDEX($C$11:$AL$11,AL$2-Inputs!$D$16),0) -> 11
A15: Compliance clients signed | C15: =Schedules!C12 -> 0 | D15: =Schedules!D12 -> 0 | E15: =Schedules!E12 -> 1 | F15: =Schedules!F12 -> 0 | G15: =Schedules!G12 -> 0 | H15: =Schedules!H12 -> 1 | I15: =Schedules!I12 -> 0 | J15: =Schedules!J12 -> 0 | ... AL15: =Schedules!AL12 -> 0
A16: Compliance clients on retainer | C16: =0+0 -> 0 | D16: =C16+C15 -> 0 | E16: =D16+D15 -> 0 | F16: =E16+E15 -> 1 | G16: =F16+F15 -> 1 | H16: =G16+G15 -> 1 | I16: =H16+H15 -> 2 | J16: =I16+I15 -> 2 | K16: =J16+J15 -> 2 | ... AL16: =AK16+AK15 -> 12
A17: Revenue ($)
A18: Escalator factor | C18: =(1+Inputs!$D$13)^(C$3-1) -> 1 | D18: =(1+Inputs!$D$13)^(D$3-1) -> 1 | E18: =(1+Inputs!$D$13)^(E$3-1) -> 1 | F18: =(1+Inputs!$D$13)^(F$3-1) -> 1 | G18: =(1+Inputs!$D$13)^(G$3-1) -> 1 | H18: =(1+Inputs!$D$13)^(H$3-1) -> 1 | I18: =(1+Inputs!$D$13)^(I$3-1) -> 1 | J18: =(1+Inputs!$D$13)^(J$3-1) -> 1 | ... AL18: =(1+Inputs!$D$13)^(AL$3-1) -> 1.1025
A19: Subscriptions | C19: =(C12*Inputs!$D$10+C13*Inputs!$D$8)*C18 -> 0 | D19: =(D12*Inputs!$D$10+D13*Inputs!$D$8)*D18 -> 0 | E19: =(E12*Inputs!$D$10+E13*Inputs!$D$8)*E18 -> 0 | F19: =(F12*Inputs!$D$10+F13*Inputs!$D$8)*F18 -> 3000 | G19: =(G12*Inputs!$D$10+G13*Inputs!$D$8)*G18 -> 3000 | H19: =(H12*Inputs!$D$10+H13*Inputs!$D$8)*H18 -> 3000 | I19: =(I12*Inputs!$D$10+I13*Inputs!$D$8)*I18 -> 3000 | J19: =(J12*Inputs!$D$10+J13*Inputs!$D$8)*J18 -> 3000 | ... AL19: =(AL12*Inputs!$D$10+AL13*Inputs!$D$8)*AL18 -> 33626.25
A20: Workflow add-ons | C20: =C14*Inputs!$D$14*Inputs!$D$15*C18 -> 0 | D20: =D14*Inputs!$D$14*Inputs!$D$15*D18 -> 0 | E20: =E14*Inputs!$D$14*Inputs!$D$15*E18 -> 0 | F20: =F14*Inputs!$D$14*Inputs!$D$15*F18 -> 0 | G20: =G14*Inputs!$D$14*Inputs!$D$15*G18 -> 0 | H20: =H14*Inputs!$D$14*Inputs!$D$15*H18 -> 250 | I20: =I14*Inputs!$D$14*Inputs!$D$15*I18 -> 250 | J20: =J14*Inputs!$D$14*Inputs!$D$15*J18 -> 250 | ... AL20: =AL14*Inputs!$D$14*Inputs!$D$15*AL18 -> 3031.875
A21: Setup and implementation | C21: =C8*Inputs!$D$9*Inputs!$D$11+C9*Inputs!$D$9*(1-Inputs!$D$11)+C7*Inputs!$D$7*Inputs!$D$11+C10*Inputs!$D$7*(1-Inputs!$D$11) -> 10000 | D21: =D8*Inputs!$D$9*Inputs!$D$11+D9*Inputs!$D$9*(1-Inputs!$D$11)+D7*Inputs!$D$7*Inputs!$D$11+D10*Inputs!$D$7*(1-Inputs!$D$11) -> 0 | E21: =E8*Inputs!$D$9*Inputs!$D$11+E9*Inputs!$D$9*(1-Inputs!$D$11)+E7*Inputs!$D$7*Inputs!$D$11+E10*Inputs!$D$7*(1-Inputs!$D$11) -> 10000 | F21: =F8*Inputs!$D$9*Inputs!$D$11+F9*Inputs!$D$9*(1-Inputs!$D$11)+F7*Inputs!$D$7*Inputs!$D$11+F10*Inputs!$D$7*(1-Inputs!$D$11) -> 0 | G21: =G8*Inputs!$D$9*Inputs!$D$11+G9*Inputs!$D$9*(1-Inputs!$D$11)+G7*Inputs!$D$7*Inputs!$D$11+G10*Inputs!$D$7*(1-Inputs!$D$11) -> 0 | H21: =H8*Inputs!$D$9*Inputs!$D$11+H9*Inputs!$D$9*(1-Inputs!$D$11)+H7*Inputs!$D$7*Inputs!$D$11+H10*Inputs!$D$7*(1-Inputs!$D$11) -> 0 | I21: =I8*Inputs!$D$9*Inputs!$D$11+I9*Inputs!$D$9*(1-Inputs!$D$11)+I7*Inputs!$D$7*Inputs!$D$11+I10*Inputs!$D$7*(1-Inputs!$D$11) -> 7500 | J21: =J8*Inputs!$D$9*Inputs!$D$11+J9*Inputs!$D$9*(1-Inputs!$D$11)+J7*Inputs!$D$7*Inputs!$D$11+J10*Inputs!$D$7*(1-Inputs!$D$11) -> 0 | ... AL21: =AL8*Inputs!$D$9*Inputs!$D$11+AL9*Inputs!$D$9*(1-Inputs!$D$11)+AL7*Inputs!$D$7*Inputs!$D$11+AL10*Inputs!$D$7*(1-Inputs!$D$11) -> 15000
A22: Hardware margin | C22: =(C9+C10)*Inputs!$D$17*Inputs!$D$18 -> 0 | D22: =(D9+D10)*Inputs!$D$17*Inputs!$D$18 -> 0 | E22: =(E9+E10)*Inputs!$D$17*Inputs!$D$18 -> 2240 | F22: =(F9+F10)*Inputs!$D$17*Inputs!$D$18 -> 0 | G22: =(G9+G10)*Inputs!$D$17*Inputs!$D$18 -> 0 | H22: =(H9+H10)*Inputs!$D$17*Inputs!$D$18 -> 0 | I22: =(I9+I10)*Inputs!$D$17*Inputs!$D$18 -> 0 | J22: =(J9+J10)*Inputs!$D$17*Inputs!$D$18 -> 0 | ... AL22: =(AL9+AL10)*Inputs!$D$17*Inputs!$D$18 -> 2240
A23: Contractor compliance | C23: =C15*Inputs!$D$20+C16*Inputs!$D$21 -> 0 | D23: =D15*Inputs!$D$20+D16*Inputs!$D$21 -> 0 | E23: =E15*Inputs!$D$20+E16*Inputs!$D$21 -> 3000 | F23: =F15*Inputs!$D$20+F16*Inputs!$D$21 -> 400 | G23: =G15*Inputs!$D$20+G16*Inputs!$D$21 -> 400 | H23: =H15*Inputs!$D$20+H16*Inputs!$D$21 -> 3400 | I23: =I15*Inputs!$D$20+I16*Inputs!$D$21 -> 800 | J23: =J15*Inputs!$D$20+J16*Inputs!$D$21 -> 800 | ... AL23: =AL15*Inputs!$D$20+AL16*Inputs!$D$21 -> 4800
A24: Industrial projects | C24: =Schedules!C13 -> 0 | D24: =Schedules!D13 -> 0 | E24: =Schedules!E13 -> 0 | F24: =Schedules!F13 -> 0 | G24: =Schedules!G13 -> 0 | H24: =Schedules!H13 -> 0 | I24: =Schedules!I13 -> 0 | J24: =Schedules!J13 -> 0 | ... AL24: =Schedules!AL13 -> 0
A25: Total revenue | C25: =SUM(C19:C24) -> 10000 | D25: =SUM(D19:D24) -> 0 | E25: =SUM(E19:E24) -> 15240 | F25: =SUM(F19:F24) -> 3400 | G25: =SUM(G19:G24) -> 3400 | H25: =SUM(H19:H24) -> 6650 | I25: =SUM(I19:I24) -> 11550 | J25: =SUM(J19:J24) -> 4050 | ... AL25: =SUM(AL19:AL24) -> 58698.125
A26: MRR (subscriptions + add-ons + retainers) | C26: =C19+C20+C16*Inputs!$D$21 -> 0 | D26: =D19+D20+D16*Inputs!$D$21 -> 0 | E26: =E19+E20+E16*Inputs!$D$21 -> 0 | F26: =F19+F20+F16*Inputs!$D$21 -> 3400 | G26: =G19+G20+G16*Inputs!$D$21 -> 3400 | H26: =H19+H20+H16*Inputs!$D$21 -> 3650 | I26: =I19+I20+I16*Inputs!$D$21 -> 4050 | J26: =J19+J20+J16*Inputs!$D$21 -> 4050 | ... AL26: =AL19+AL20+AL16*Inputs!$D$21 -> 41458.125
A27: Gross profit ($)
A28: Cost of revenue | C28: =C21*(1-Inputs!$D$23)+C19*(1-Inputs!$D$24)+C20*(1-Inputs!$D$25)+C22*(1-Inputs!$D$26)+C23*(1-Inputs!$D$27)+C24*(1-Inputs!$D$28) -> 4500 | D28: =D21*(1-Inputs!$D$23)+D19*(1-Inputs!$D$24)+D20*(1-Inputs!$D$25)+D22*(1-Inputs!$D$26)+D23*(1-Inputs!$D$27)+D24*(1-Inputs!$D$28) -> 0 | E28: =E21*(1-Inputs!$D$23)+E19*(1-Inputs!$D$24)+E20*(1-Inputs!$D$25)+E22*(1-Inputs!$D$26)+E23*(1-Inputs!$D$27)+E24*(1-Inputs!$D$28) -> 5100 | F28: =F21*(1-Inputs!$D$23)+F19*(1-Inputs!$D$24)+F20*(1-Inputs!$D$25)+F22*(1-Inputs!$D$26)+F23*(1-Inputs!$D$27)+F24*(1-Inputs!$D$28) -> 980 | G28: =G21*(1-Inputs!$D$23)+G19*(1-Inputs!$D$24)+G20*(1-Inputs!$D$25)+G22*(1-Inputs!$D$26)+G23*(1-Inputs!$D$27)+G24*(1-Inputs!$D$28) -> 980 | H28: =H21*(1-Inputs!$D$23)+H19*(1-Inputs!$D$24)+H20*(1-Inputs!$D$25)+H22*(1-Inputs!$D$26)+H23*(1-Inputs!$D$27)+H24*(1-Inputs!$D$28) -> 1617.5 | I28: =I21*(1-Inputs!$D$23)+I19*(1-Inputs!$D$24)+I20*(1-Inputs!$D$25)+I22*(1-Inputs!$D$26)+I23*(1-Inputs!$D$27)+I24*(1-Inputs!$D$28) -> 4472.5 | J28: =J21*(1-Inputs!$D$23)+J19*(1-Inputs!$D$24)+J20*(1-Inputs!$D$25)+J22*(1-Inputs!$D$26)+J23*(1-Inputs!$D$27)+J24*(1-Inputs!$D$28) -> 1097.5 | ... AL28: =AL21*(1-Inputs!$D$23)+AL19*(1-Inputs!$D$24)+AL20*(1-Inputs!$D$25)+AL22*(1-Inputs!$D$26)+AL23*(1-Inputs!$D$27)+AL24*(1-Inputs!$D$28) -> 18252.656
A29: Gross profit | C29: =C25-C28 -> 5500 | D29: =D25-D28 -> 0 | E29: =E25-E28 -> 10140 | F29: =F25-F28 -> 2420 | G29: =G25-G28 -> 2420 | H29: =H25-H28 -> 5032.5 | I29: =I25-I28 -> 7077.5 | J29: =J25-J28 -> 2952.5 | ... AL29: =AL25-AL28 -> 40445.469
A30: Operating costs ($)
A31: Founder salary | C31: =CHOOSE(C$3,Inputs!$D$30,Inputs!$D$31,Inputs!$D$32)/12 -> 5833.3333 | D31: =CHOOSE(D$3,Inputs!$D$30,Inputs!$D$31,Inputs!$D$32)/12 -> 5833.3333 | E31: =CHOOSE(E$3,Inputs!$D$30,Inputs!$D$31,Inputs!$D$32)/12 -> 5833.3333 | F31: =CHOOSE(F$3,Inputs!$D$30,Inputs!$D$31,Inputs!$D$32)/12 -> 5833.3333 | G31: =CHOOSE(G$3,Inputs!$D$30,Inputs!$D$31,Inputs!$D$32)/12 -> 5833.3333 | H31: =CHOOSE(H$3,Inputs!$D$30,Inputs!$D$31,Inputs!$D$32)/12 -> 5833.3333 | I31: =CHOOSE(I$3,Inputs!$D$30,Inputs!$D$31,Inputs!$D$32)/12 -> 5833.3333 | J31: =CHOOSE(J$3,Inputs!$D$30,Inputs!$D$31,Inputs!$D$32)/12 -> 5833.3333 | ... AL31: =CHOOSE(AL$3,Inputs!$D$30,Inputs!$D$31,Inputs!$D$32)/12 -> 10833.333
A32: Employer payroll taxes (founder) | C32: =C31*Inputs!$D$33 -> 446.25 | D32: =D31*Inputs!$D$33 -> 446.25 | E32: =E31*Inputs!$D$33 -> 446.25 | F32: =F31*Inputs!$D$33 -> 446.25 | G32: =G31*Inputs!$D$33 -> 446.25 | H32: =H31*Inputs!$D$33 -> 446.25 | I32: =I31*Inputs!$D$33 -> 446.25 | J32: =J31*Inputs!$D$33 -> 446.25 | ... AL32: =AL31*Inputs!$D$33 -> 828.75
A33: Staff (loaded) | C33: =IF(C$2>=Inputs!$D$34,Inputs!$D$35/12,0)+IF(C$2>=Inputs!$D$36,Inputs!$D$37/12,0) -> 0 | D33: =IF(D$2>=Inputs!$D$34,Inputs!$D$35/12,0)+IF(D$2>=Inputs!$D$36,Inputs!$D$37/12,0) -> 0 | E33: =IF(E$2>=Inputs!$D$34,Inputs!$D$35/12,0)+IF(E$2>=Inputs!$D$36,Inputs!$D$37/12,0) -> 0 | F33: =IF(F$2>=Inputs!$D$34,Inputs!$D$35/12,0)+IF(F$2>=Inputs!$D$36,Inputs!$D$37/12,0) -> 0 | G33: =IF(G$2>=Inputs!$D$34,Inputs!$D$35/12,0)+IF(G$2>=Inputs!$D$36,Inputs!$D$37/12,0) -> 0 | H33: =IF(H$2>=Inputs!$D$34,Inputs!$D$35/12,0)+IF(H$2>=Inputs!$D$36,Inputs!$D$37/12,0) -> 0 | I33: =IF(I$2>=Inputs!$D$34,Inputs!$D$35/12,0)+IF(I$2>=Inputs!$D$36,Inputs!$D$37/12,0) -> 0 | J33: =IF(J$2>=Inputs!$D$34,Inputs!$D$35/12,0)+IF(J$2>=Inputs!$D$36,Inputs!$D$37/12,0) -> 0 | ... AL33: =IF(AL$2>=Inputs!$D$34,Inputs!$D$35/12,0)+IF(AL$2>=Inputs!$D$36,Inputs!$D$37/12,0) -> 7291.6667
A34: Contract engineer + student | C34: =IF(AND(C$2>=Inputs!$D$38,C$2<Inputs!$D$34),Inputs!$D$39+Inputs!$D$40,0) -> 0 | D34: =IF(AND(D$2>=Inputs!$D$38,D$2<Inputs!$D$34),Inputs!$D$39+Inputs!$D$40,0) -> 0 | E34: =IF(AND(E$2>=Inputs!$D$38,E$2<Inputs!$D$34),Inputs!$D$39+Inputs!$D$40,0) -> 0 | F34: =IF(AND(F$2>=Inputs!$D$38,F$2<Inputs!$D$34),Inputs!$D$39+Inputs!$D$40,0) -> 0 | G34: =IF(AND(G$2>=Inputs!$D$38,G$2<Inputs!$D$34),Inputs!$D$39+Inputs!$D$40,0) -> 0 | H34: =IF(AND(H$2>=Inputs!$D$38,H$2<Inputs!$D$34),Inputs!$D$39+Inputs!$D$40,0) -> 2300 | I34: =IF(AND(I$2>=Inputs!$D$38,I$2<Inputs!$D$34),Inputs!$D$39+Inputs!$D$40,0) -> 2300 | J34: =IF(AND(J$2>=Inputs!$D$38,J$2<Inputs!$D$34),Inputs!$D$39+Inputs!$D$40,0) -> 2300 | ... AL34: =IF(AND(AL$2>=Inputs!$D$38,AL$2<Inputs!$D$34),Inputs!$D$39+Inputs!$D$40,0) -> 0
A35: Memberships, events, travel | C35: =Inputs!$D$42/12 -> 2083.3333 | D35: =Inputs!$D$42/12 -> 2083.3333 | E35: =Inputs!$D$42/12 -> 2083.3333 | F35: =Inputs!$D$42/12 -> 2083.3333 | G35: =Inputs!$D$42/12 -> 2083.3333 | H35: =Inputs!$D$42/12 -> 2083.3333 | I35: =Inputs!$D$42/12 -> 2083.3333 | J35: =Inputs!$D$42/12 -> 2083.3333 | ... AL35: =Inputs!$D$42/12 -> 2083.3333
A36: Insurance (incl. key-person) | C36: =(Inputs!$D$43+Inputs!$D$44)/12 -> 766.66667 | D36: =(Inputs!$D$43+Inputs!$D$44)/12 -> 766.66667 | E36: =(Inputs!$D$43+Inputs!$D$44)/12 -> 766.66667 | F36: =(Inputs!$D$43+Inputs!$D$44)/12 -> 766.66667 | G36: =(Inputs!$D$43+Inputs!$D$44)/12 -> 766.66667 | H36: =(Inputs!$D$43+Inputs!$D$44)/12 -> 766.66667 | I36: =(Inputs!$D$43+Inputs!$D$44)/12 -> 766.66667 | J36: =(Inputs!$D$43+Inputs!$D$44)/12 -> 766.66667 | ... AL36: =(Inputs!$D$43+Inputs!$D$44)/12 -> 766.66667
A37: Software, tools, hosting | C37: =Inputs!$D$45 -> 1000 | D37: =Inputs!$D$45 -> 1000 | E37: =Inputs!$D$45 -> 1000 | F37: =Inputs!$D$45 -> 1000 | G37: =Inputs!$D$45 -> 1000 | H37: =Inputs!$D$45 -> 1000 | I37: =Inputs!$D$45 -> 1000 | J37: =Inputs!$D$45 -> 1000 | ... AL37: =Inputs!$D$45 -> 1000
A38: Professional fees + formation | C38: =Inputs!$D$46+IF(C$2<=3,Inputs!$D$47/3,0) -> 5000 | D38: =Inputs!$D$46+IF(D$2<=3,Inputs!$D$47/3,0) -> 5000 | E38: =Inputs!$D$46+IF(E$2<=3,Inputs!$D$47/3,0) -> 5000 | F38: =Inputs!$D$46+IF(F$2<=3,Inputs!$D$47/3,0) -> 1000 | G38: =Inputs!$D$46+IF(G$2<=3,Inputs!$D$47/3,0) -> 1000 | H38: =Inputs!$D$46+IF(H$2<=3,Inputs!$D$47/3,0) -> 1000 | I38: =Inputs!$D$46+IF(I$2<=3,Inputs!$D$47/3,0) -> 1000 | J38: =Inputs!$D$46+IF(J$2<=3,Inputs!$D$47/3,0) -> 1000 | ... AL38: =Inputs!$D$46+IF(AL$2<=3,Inputs!$D$47/3,0) -> 1000
A39: Unitemized (calibrated) | C39: =CHOOSE(C$3,Inputs!$D$48,Inputs!$D$49,Inputs!$D$50)/12 -> 2716.5833 | D39: =CHOOSE(D$3,Inputs!$D$48,Inputs!$D$49,Inputs!$D$50)/12 -> 2716.5833 | E39: =CHOOSE(E$3,Inputs!$D$48,Inputs!$D$49,Inputs!$D$50)/12 -> 2716.5833 | F39: =CHOOSE(F$3,Inputs!$D$48,Inputs!$D$49,Inputs!$D$50)/12 -> 2716.5833 | G39: =CHOOSE(G$3,Inputs!$D$48,Inputs!$D$49,Inputs!$D$50)/12 -> 2716.5833 | H39: =CHOOSE(H$3,Inputs!$D$48,Inputs!$D$49,Inputs!$D$50)/12 -> 2716.5833 | I39: =CHOOSE(I$3,Inputs!$D$48,Inputs!$D$49,Inputs!$D$50)/12 -> 2716.5833 | J39: =CHOOSE(J$3,Inputs!$D$48,Inputs!$D$49,Inputs!$D$50)/12 -> 2716.5833 | ... AL39: =CHOOSE(AL$3,Inputs!$D$48,Inputs!$D$49,Inputs!$D$50)/12 -> 4815.4167
A40: Total operating costs | C40: =SUM(C31:C39) -> 17846.167 | D40: =SUM(D31:D39) -> 17846.167 | E40: =SUM(E31:E39) -> 17846.167 | F40: =SUM(F31:F39) -> 13846.167 | G40: =SUM(G31:G39) -> 13846.167 | H40: =SUM(H31:H39) -> 16146.167 | I40: =SUM(I31:I39) -> 16146.167 | J40: =SUM(J31:J39) -> 16146.167 | ... AL40: =SUM(AL31:AL39) -> 28619.167
A41: Operating result | C41: =C29-C40 -> -12346.167 | D41: =D29-D40 -> -17846.167 | E41: =E29-E40 -> -7706.1667 | F41: =F29-F40 -> -11426.167 | G41: =G29-G40 -> -11426.167 | H41: =H29-H40 -> -11113.667 | I41: =I29-I40 -> -9068.6667 | J41: =J29-J40 -> -13193.667 | ... AL41: =AL29-AL40 -> 11826.302
...

Sheet M_Base
A1: Base — monthly model (all cells are formulas)
A2: Month | C2: 1 | D2: 2 | E2: 3 | F2: 4 | G2: 5 | H2: 6 | I2: 7 | J2: 8 | K2: 9 | L2: 10 | M2: 11 | N2: 12 | O2: 13 | P2: 14 | Q2: 15 | R2: 16 | S2: 17 | T2: 18 | U2: 19 | V2: 20 | W2: 21 | X2: 22 | Y2: 23 | Z2: 24 | AA2: 25 | AB2: 26 | AC2: 27 | AD2: 28 | AE2: 29 | AF2: 30 | AG2: 31 | AH2: 32 | AI2: 33 | AJ2: 34 | AK2: 35 | AL2: 36
A3: Model year | C3: =ROUNDUP(C2/12,0) -> 1 | D3: =ROUNDUP(D2/12,0) -> 1 | E3: =ROUNDUP(E2/12,0) -> 1 | F3: =ROUNDUP(F2/12,0) -> 1 | G3: =ROUNDUP(G2/12,0) -> 1 | H3: =ROUNDUP(H2/12,0) -> 1 | I3: =ROUNDUP(I2/12,0) -> 1 | J3: =ROUNDUP(J2/12,0) -> 1 | ... AL3: =ROUNDUP(AL2/12,0) -> 3
